<?xml version="1.0" encoding="utf-8"?>
<robot name="T170A">
  <link name="base_link">
    <inertial>
      <origin xyz="0.00914372 -0.00010753 0.01430216" rpy="0 0 0" />
      <mass value="4.99181163" />
      <inertia ixx="0.03994737" ixy="-0.00001216" ixz="0.00262875" iyy="0.01559523" iyz="-0.00001248" izz="0.04887369" />
    </inertial>
    <visual>
      <origin xyz="0 0 0" rpy="0 0 0" />
      <geometry>
        <mesh filename="package://T170A/meshes/base_link.STL" />
      </geometry>
      <material name="">
        <color rgba="0.898039215686275 0.917647058823529 0.929411764705882 1" />
      </material>
    </visual>
    <collision>
      <origin xyz="0 0 0" rpy="0 0 0" />
      <geometry>
        <mesh filename="package://T170A/meshes/base_link.STL" />
      </geometry>
    </collision>
  </link>
  <link name="waist_roll_link">
    <inertial>
      <origin xyz="0.00000000 -0.00391749 0.04836016" rpy="0 0 0" />
      <mass value="1.11122048" />
      <inertia ixx="0.00100782" ixy="0.00000000" ixz="0.00000000" iyy="0.00104544" iyz="0.00001930" izz="0.00083224" />
    </inertial>
    <visual>
      <origin xyz="0 0 0" rpy="0 0 0" />
      <geometry>
        <mesh filename="package://T170A/meshes/waist_roll_link.STL" />
      </geometry>
      <material name="">
        <color rgba="0.898039215686275 0.917647058823529 0.929411764705882 1" />
      </material>
    </visual>
    <collision>
      <origin xyz="0 0 0" rpy="0 0 0" />
      <geometry>
        <mesh filename="package://T170A/meshes/waist_roll_link.STL" />
      </geometry>
    </collision>
  </link>
  <joint name="waist_roll" type="revolute">
    <origin xyz="-0.0058 0 0.0373914474349936" rpy="1.5707963267949 0 1.5707963267949" />
    <parent link="base_link" />
    <child link="waist_roll_link" />
    <axis xyz="0 0 1" />
    <limit lower="-0.52" upper="0.52" effort="102" velocity="3.14" />
  </joint>
  <link name="waist_yaw_link">
    <inertial>
      <origin xyz="0.00035796 0.00043759 0.05079813" rpy="0 0 0" />
      <mass value="1.43155342" />
      <inertia ixx="0.00178465" ixy="0.00001789" ixz="-0.00000118" iyy="0.00149309" iyz="-0.00000415" izz="0.00161635" />
    </inertial>
    <visual>
      <origin xyz="0 0 0" rpy="0 0 0" />
      <geometry>
        <mesh filename="package://T170A/meshes/waist_yaw_link.STL" />
      </geometry>
      <material name="">
        <color rgba="0.898039215686275 0.917647058823529 0.929411764705882 1" />
      </material>
    </visual>
    <collision>
      <origin xyz="0 0 0" rpy="0 0 0" />
      <geometry>
        <mesh filename="package://T170A/meshes/waist_yaw_link.STL" />
      </geometry>
    </collision>
  </link>
  <joint name="waist_yaw" type="revolute">
    <origin xyz="0 0.0319999999999935 0.0527999995489399" rpy="1.5707963267949 -1.5707963267949 3.1416" />
    <parent link="waist_roll_link" />
    <child link="waist_yaw_link" />
    <axis xyz="0 0 1" />
    <limit lower="-3.14" upper="3.14" effort="102" velocity="3.14" />
  </joint>
  <link name="waist_pitch_link">
    <inertial>
      <origin xyz="0.01866267 0.17719713 -0.04832598" rpy="0 0 0" />
      <mass value="5.70818625" />
      <inertia ixx="0.05509794" ixy="0.00418492" ixz="-0.00008181" iyy="0.02660924" iyz="-0.00080260" izz="0.04255708" />
    </inertial>
    <visual>
      <origin xyz="0 0 0" rpy="0 0 0" />
      <geometry>
        <mesh filename="package://T170A/meshes/waist_pitch_link.STL" />
      </geometry>
      <material name="">
        <color rgba="0.898039215686275 0.917647058823529 0.929411764705882 1" />
      </material>
    </visual>
    <collision>
      <origin xyz="0 0 0" rpy="0 0 0" />
      <geometry>
        <mesh filename="package://T170A/meshes/waist_pitch_link.STL" />
      </geometry>
    </collision>
  </link>
  <joint name="waist_pitch" type="revolute">
    <origin xyz="0 0.0475 0.054797" rpy="1.5708 0 3.1416" />
    <parent link="waist_yaw_link" />
    <child link="waist_pitch_link" />
    <axis xyz="0 0 1" />
    <limit lower="0" upper="0.52" effort="102" velocity="3.14" />
  </joint>
  <link name="head_yaw_link">
    <inertial>
      <origin xyz="0.00000000 -0.01761786 0.04121872" rpy="0 0 0" />
      <mass value="0.38415471" />
      <inertia ixx="0.00036023" ixy="0.00000000" ixz="0.00000000" iyy="0.00027558" iyz="0.00007698" izz="0.00019098" />
    </inertial>
    <visual>
      <origin xyz="0 0 0" rpy="0 0 0" />
      <geometry>
        <mesh filename="package://T170A/meshes/head_yaw_link.STL" />
      </geometry>
      <material name="">
        <color rgba="0.792156862745098 0.819607843137255 0.929411764705882 1" />
      </material>
    </visual>
    <collision>
      <origin xyz="0 0 0" rpy="0 0 0" />
      <geometry>
        <mesh filename="package://T170A/meshes/head_yaw_link.STL" />
      </geometry>
    </collision>
  </link>
  <joint name="head_yaw" type="revolute">
    <origin xyz="0 0.29600269667174 -0.0474999999999997" rpy="1.5707963267949 0 -3.14159265358979" />
    <parent link="waist_pitch_link" />
    <child link="head_yaw_link" />
    <axis xyz="0 0 1" />
    <limit lower="-3.14" upper="3.14" effort="11" velocity="4.18" />
  </joint>
  <link name="head_pitch_link">
    <inertial>
      <origin xyz="0.00008283 0.00000000 -0.02383380" rpy="0 0 0" />
      <mass value="0.27667557" />
      <inertia ixx="0.00008581" ixy="0.00000000" ixz="-0.00000646" iyy="0.00012860" iyz="0.00000000" izz="0.00009605" />
    </inertial>
    <visual>
      <origin xyz="0 0 0" rpy="0 0 0" />
      <geometry>
        <mesh filename="package://T170A/meshes/head_pitch_link.STL" />
      </geometry>
      <material name="">
        <color rgba="0.647058823529412 0.619607843137255 0.588235294117647 1" />
      </material>
    </visual>
    <collision>
      <origin xyz="0 0 0" rpy="0 0 0" />
      <geometry>
        <mesh filename="package://T170A/meshes/head_pitch_link.STL" />
      </geometry>
    </collision>
  </link>
  <joint name="head_pitch" type="revolute">
    <origin xyz="0 -0.0300000000000001 0.082" rpy="1.5707963267949 0 0" />
    <parent link="head_yaw_link" />
    <child link="head_pitch_link" />
    <axis xyz="0 0 1" />
    <limit lower="-0.52" upper="0.52" effort="4.8" velocity="4.71" />
  </joint>
  <link name="head_roll_link">
    <inertial>
      <origin xyz="-0.07585725 0.00000712 0.00844140" rpy="0 0 0" />
      <mass value="0.12942875" />
      <inertia ixx="0.00005655" ixy="0.00000000" ixz="-0.00001927" iyy="0.00022418" iyz="-0.00000003" izz="0.00021978" />
    </inertial>
    <visual>
      <origin xyz="0 0 0" rpy="0 0 0" />
      <geometry>
        <mesh filename="package://T170A/meshes/head_roll_link.STL" />
      </geometry>
      <material name="">
        <color rgba="0.898039215686275 0.917647058823529 0.929411764705882 1" />
      </material>
    </visual>
    <collision>
      <origin xyz="0 0 0" rpy="0 0 0" />
      <geometry>
        <mesh filename="package://T170A/meshes/head_roll_link.STL" />
      </geometry>
    </collision>
  </link>
  <joint name="head_roll" type="revolute">
    <origin xyz="0.0260000000000001 0 -0.0300000000000011" rpy="-1.5707963267949 0 -1.5707963267949" />
    <parent link="head_pitch_link" />
    <child link="head_roll_link" />
    <axis xyz="0 0 1" />
    <limit lower="-0.52" upper="0.52" effort="4.8" velocity="4.71" />
  </joint>
  <link name="right_shoulder_pitch_link">
    <inertial>
      <origin xyz="-0.00245769 -0.00002314 0.05698226" rpy="0 0 0" />
      <mass value="0.85228830" />
      <inertia ixx="0.00073887" ixy="0.00000011" ixz="0.00001889" iyy="0.00076588" iyz="0.00000009" izz="0.00056064" />
    </inertial>
    <visual>
      <origin xyz="0 0 0" rpy="0 0 0" />
      <geometry>
        <mesh filename="package://T170A/meshes/right_shoulder_pitch_link.STL" />
      </geometry>
      <material name="">
        <color rgba="0.898039215686275 0.917647058823529 0.929411764705882 1" />
      </material>
    </visual>
    <collision>
      <origin xyz="0 0 0" rpy="0 0 0" />
      <geometry>
        <mesh filename="package://T170A/meshes/right_shoulder_pitch_link.STL" />
      </geometry>
    </collision>
  </link>
  <joint name="right_shoulder_pitch" type="revolute">
    <origin xyz="0 0.262002696671743 -0.17535" rpy="-3.14159265358979 0 -3.14159265358979" />
    <parent link="waist_pitch_link" />
    <child link="right_shoulder_pitch_link" />
    <axis xyz="0 0 1" />
    <limit lower="-0.087" upper="2.09" effort="66" velocity="3.56" />
  </joint>
  <link name="right_shoulder_roll_link">
    <inertial>
      <origin xyz="-0.23117234 0.03992204 -0.03152184" rpy="0 0 0" />
      <mass value="0.57830504" />
      <inertia ixx="0.00028483" ixy="0.00008463" ixz="-0.00000022" iyy="0.00082683" iyz="-0.00000028" izz="0.00085743" />
    </inertial>
    <visual>
      <origin xyz="0 0 0" rpy="0 0 0" />
      <geometry>
        <mesh filename="package://T170A/meshes/right_shoulder_roll_link.STL" />
      </geometry>
      <material name="">
        <color rgba="0.898039215686275 0.917647058823529 0.929411764705882 1" />
      </material>
    </visual>
    <collision>
      <origin xyz="0 0 0" rpy="0 0 0" />
      <geometry>
        <mesh filename="package://T170A/meshes/right_shoulder_roll_link.STL" />
      </geometry>
    </collision>
  </link>
  <joint name="right_shoulder_roll" type="revolute">
    <origin xyz="0.0315 0 0.06315" rpy="1.5708 0 1.5708" />
    <parent link="right_shoulder_pitch_link" />
    <child link="right_shoulder_roll_link" />
    <axis xyz="0 0 1" />
    <limit lower="-2.96" upper="0.52" effort="66" velocity="3.56" />
  </joint>
  <link name="right_elbow_yaw_link">
    <inertial>
      <origin xyz="0.00022157 0.00000000 0.16926006" rpy="0 0 0" />
      <mass value="0.44339888" />
      <inertia ixx="0.00042265" ixy="0.00000000" ixz="0.00000065" iyy="0.00049068" iyz="0.00000000" izz="0.00024339" />
    </inertial>
    <visual>
      <origin xyz="0 0 0" rpy="0 0 0" />
      <geometry>
        <mesh filename="package://T170A/meshes/right_elbow_yaw_link.STL" />
      </geometry>
      <material name="">
        <color rgba="0.898039215686275 0.917647058823529 0.929411764705882 1" />
      </material>
    </visual>
    <collision>
      <origin xyz="0 0 0" rpy="0 0 0" />
      <geometry>
        <mesh filename="package://T170A/meshes/right_elbow_yaw_link.STL" />
      </geometry>
    </collision>
  </link>
  <joint name="right_elbow_yaw" type="revolute">
    <origin xyz="-0.140335104804241 0.0247448653175387 -0.0314999999999975" rpy="1.5707963267949 0 -1.74532925199432" />
    <parent link="right_shoulder_roll_link" />
    <child link="right_elbow_yaw_link" />
    <axis xyz="0 0 1" />
    <limit lower="-1.57" upper="1.57" effort="34" velocity="3.87" />
  </joint>
  <link name="right_elbow_pitch_link">
    <inertial>
      <origin xyz="0.00000000 -0.06176006 -0.02982157" rpy="0 0 0" />
      <mass value="0.44339888" />
      <inertia ixx="0.00049068" ixy="0.00000000" ixz="0.00000000" iyy="0.00024339" iyz="0.00000065" izz="0.00042265" />
    </inertial>
    <visual>
      <origin xyz="0 0 0" rpy="0 0 0" />
      <geometry>
        <mesh filename="package://T170A/meshes/right_elbow_pitch_link.STL" />
      </geometry>
      <material name="">
        <color rgba="0.898039215686275 0.917647058823529 0.929411764705882 1" />
      </material>
    </visual>
    <collision>
      <origin xyz="0 0 0" rpy="0 0 0" />
      <geometry>
        <mesh filename="package://T170A/meshes/right_elbow_pitch_link.STL" />
      </geometry>
    </collision>
  </link>
  <joint name="right_elbow_pitch" type="revolute">
    <origin xyz="-0.029599999999998 0 0.107499999999999" rpy="-1.5707963267949 0 1.5707963267949" />
    <parent link="right_elbow_yaw_link" />
    <child link="right_elbow_pitch_link" />
    <axis xyz="0 0 1" />
    <limit lower="0" upper="1.92" effort="34" velocity="3.87" />
  </joint>
  <link name="right_wrist_yaw_link">
    <inertial>
      <origin xyz="0.00000000 0.02114613 0.05641941" rpy="0 0 0" />
      <mass value="0.45693555" />
      <inertia ixx="0.00103526" ixy="0.00000000" ixz="-0.00000236" iyy="0.00094735" iyz="-0.00019373" izz="0.00022182" />
    </inertial>
    <visual>
      <origin xyz="0 0 0" rpy="0 0 0" />
      <geometry>
        <mesh filename="package://T170A/meshes/right_wrist_yaw_link.STL" />
      </geometry>
      <material name="">
        <color rgba="0.898039215686275 0.917647058823529 0.929411764705882 1" />
      </material>
    </visual>
    <collision>
      <origin xyz="0 0 0" rpy="0 0 0" />
      <geometry>
        <mesh filename="package://T170A/meshes/right_wrist_yaw_link.STL" />
      </geometry>
    </collision>
  </link>
  <joint name="right_wrist_yaw" type="revolute">
    <origin xyz="0 -0.103500000000002 -0.0295999999999999" rpy="1.5707963267949 0 0" />
    <parent link="right_elbow_pitch_link" />
    <child link="right_wrist_yaw_link" />
    <axis xyz="0 0 1" />
    <limit lower="-3.14" upper="3.14" effort="11" velocity="4.18" />
  </joint>
  <link name="right_wrist_pitch_link">
    <inertial>
      <origin xyz="-0.00025012 0.00003431 0.02692981" rpy="0 0 0" />
      <mass value="0.28016455" />
      <inertia ixx="0.00008640" ixy="0.00000025" ixz="0.00000695" iyy="0.00013132" iyz="-0.00000009" izz="0.00009909" />
    </inertial>
    <visual>
      <origin xyz="0 0 0" rpy="0 0 0" />
      <geometry>
        <mesh filename="package://T170A/meshes/right_wrist_pitch_link.STL" />
      </geometry>
      <material name="">
        <color rgba="0.647058823529412 0.619607843137255 0.588235294117647 1" />
      </material>
    </visual>
    <collision>
      <origin xyz="0 0 0" rpy="0 0 0" />
      <geometry>
        <mesh filename="package://T170A/meshes/right_wrist_pitch_link.STL" />
      </geometry>
    </collision>
  </link>
  <joint name="right_wrist_pitch" type="revolute">
    <origin xyz="0 0.0335000000000004 0.1455" rpy="1.5707963267949 0 0" />
    <parent link="right_wrist_yaw_link" />
    <child link="right_wrist_pitch_link" />
    <axis xyz="0 0 -1" />
    <limit lower="-0.52" upper="0.52" effort="4.8" velocity="4.71" />
  </joint>
  <link name="right_wrist_roll_link">
    <inertial>
      <origin xyz="0.02437500 0.00000000 -0.02638329" rpy="0 0 0" />
      <mass value="0.04088512" />
      <inertia ixx="0.00003123" ixy="0.00000000" ixz="-0.00000263" iyy="0.00003860" iyz="0.00000000" izz="0.00001494" />
    </inertial>
    <visual>
      <origin xyz="0 0 0" rpy="0 0 0" />
      <geometry>
        <mesh filename="package://T170A/meshes/right_wrist_roll_link.STL" />
      </geometry>
      <material name="">
        <color rgba="0.529411764705882 0.549019607843137 0.549019607843137 1" />
      </material>
    </visual>
    <collision>
      <origin xyz="0 0 0" rpy="0 0 0" />
      <geometry>
        <mesh filename="package://T170A/meshes/right_wrist_roll_link.STL" />
      </geometry>
    </collision>
  </link>
  <joint name="right_wrist_roll" type="revolute">
    <origin xyz="0.026 0 0.0330000000000008" rpy="1.57079632679486 0 1.5707963267949" />
    <parent link="right_wrist_pitch_link" />
    <child link="right_wrist_roll_link" />
    <axis xyz="0 0 1" />
    <limit lower="-0.52" upper="1.57" effort="4.8" velocity="4.71" />
  </joint>
  <!-- Right hand -->
  <link name="right_hand_base_link">
    <inertial>
      <origin xyz="0.00252515168164585 -0.001960054926157 0.0660467739648412" rpy="0 0 0" />
      <mass value="0.38756" />
      <inertia ixx="0.00059831308" ixy="5.60829e-06" ixz="2.8701399999999997e-06" iyy="0.00050077156" iyz="3.4830999999999997e-06" izz="0.00018467082" />
    </inertial>
    <visual>
      <origin xyz="0 0 0" rpy="0 0 0" />
      <geometry>
        <mesh filename="package://T170A/meshes/hands/right_hand_base_link.STL" />
      </geometry>
      <material name="">
        <color rgba="1 1 1 1" />
      </material>
    </visual>
    <collision>
      <origin xyz="0 0 0" rpy="0 0 0" />
      <geometry>
        <mesh filename="package://T170A/meshes/hands/right_hand_base_link.STL" />
      </geometry>
    </collision>
  </link>
  <joint name="right_hand_base" type="fixed">
    <origin xyz="0.037 0 -0.026" rpy="1.5708 0 1.5708" />
    <parent link="right_wrist_roll_link" />
    <child link="right_hand_base_link" />
  </joint>
  <link name="right_thumb_1">
    <inertial>
      <origin xyz="0.000853491366153925 0.00482216769884483 -0.00481999614705116" rpy="0 0 0" />
      <mass value="0.00483" />
      <inertia ixx="1.9502e-07" ixy="-3.536e-08" ixz="-3.1e-09" iyy="1.4336e-07" iyz="-7.9e-09" izz="1.6891e-07" />
    </inertial>
    <visual>
      <origin xyz="0 0 0" rpy="0 0 0" />
      <geometry>
        <mesh filename="package://T170A/meshes/hands/right_thumb_1.STL" />
      </geometry>
      <material name="">
        <color rgba="1 1 1 1" />
      </material>
    </visual>
    <collision>
      <origin xyz="0 0 0" rpy="0 0 0" />
      <geometry>
        <mesh filename="package://T170A/meshes/hands/right_thumb_1.STL" />
      </geometry>
    </collision>
  </link>
  <joint name="right_thumb_1_joint" type="revolute">
    <origin xyz="0.0169600000000007 0.020450000002209 0.0663500000000002" rpy="0 0 0" />
    <parent link="right_hand_base_link" />
    <child link="right_thumb_1" />
    <axis xyz="0 0 -1" />
    <limit lower="0" upper="1.246165" effort="50" velocity="1" />
  </joint>
  <link name="right_thumb_2">
    <inertial>
      <origin xyz="0.0194641293930403 0.0162980383727088 -0.00803857337744943" rpy="0 0 0" />
      <mass value="0.05759" />
      <inertia ixx="1.0666209999999999e-05" ixy="-4.413609999999999e-06" ixz="-5.150000000000001e-09" iyy="8.92353e-06" iyz="2.59e-09" izz="1.700133e-05" />
    </inertial>
    <visual>
      <origin xyz="0 0 0" rpy="0 0 0" />
      <geometry>
        <mesh filename="package://T170A/meshes/hands/right_thumb_2.STL" />
      </geometry>
      <material name="">
        <color rgba="1 1 1 1" />
      </material>
    </visual>
    <collision>
      <origin xyz="0 0 0" rpy="0 0 0" />
      <geometry>
        <mesh filename="package://T170A/meshes/hands/right_thumb_2.STL" />
      </geometry>
    </collision>
  </link>
  <joint name="right_thumb_2_joint" type="revolute">
    <origin xyz="0.0107353075101483 0.00900017625730479 -0.00649999999999998" rpy="1.57079632679489 0 1.30550628049177" />
    <parent link="right_thumb_1" />
    <child link="right_thumb_2" />
    <axis xyz="0 0 1" />
    <limit lower="0" upper="0.48" effort="50" velocity="1" />
  </joint>
  <link name="right_thumb_3">
    <inertial>
      <origin xyz="0.00946651884646355 0.00207630823866701 -0.00720000588824668" rpy="0 0 0" />
      <mass value="0.00378440898138893" />
      <!-- <mass value="0.00985" /> -->
      <inertia ixx="1.21069e-06" ixy="-1.0767e-07" ixz="-1.0000000000000001e-11" iyy="6.011799999999999e-07" iyz="-3e-11" izz="1.28966e-06" />
    </inertial>
    <visual>
      <origin xyz="0 0 0" rpy="0 0 0" />
      <geometry>
        <mesh filename="package://T170A/meshes/hands/right_thumb_3.STL" />
      </geometry>
      <material name="">
        <color rgba="1 1 1 1" />
      </material>
    </visual>
    <collision>
      <origin xyz="0 0 0" rpy="0 0 0" />
      <geometry>
        <mesh filename="package://T170A/meshes/hands/right_thumb_3.STL" />
      </geometry>
    </collision>
  </link>
  <joint name="right_thumb_3_joint" type="revolute">
    <origin xyz="0.0376167925538582 0.0414855421501229 -0.000800000000000356" rpy="0 0 0" />
    <parent link="right_thumb_2" />
    <child link="right_thumb_3" />
    <axis xyz="0 0 1" />
    <limit lower="0" upper="0.3578" effort="50" velocity="1" />
    <mimic joint="right_thumb_2_joint" multiplier="1.1425" offset="0" />
  </joint>
  <link name="right_thumb_4">
    <inertial>
      <origin xyz="0.00604904909827651 0.00861522746372045 -0.00600329390500667" rpy="0 0 0" />
      <mass value="0.00552" />
      <inertia ixx="3.1668e-07" ixy="-4.536e-08" ixz="1.0000000000000001e-11" iyy="1.2999000000000001e-07" iyz="4e-10" izz="3.3747e-07" />
    </inertial>
    <visual>
      <origin xyz="0 0 0" rpy="0 0 0" />
      <geometry>
        <mesh filename="package://T170A/meshes/hands/right_thumb_4.STL" />
      </geometry>
      <material name="">
        <color rgba="1 1 1 1" />
      </material>
    </visual>
    <collision>
      <origin xyz="0 0 0" rpy="0 0 0" />
      <geometry>
        <mesh filename="package://T170A/meshes/hands/right_thumb_4.STL" />
      </geometry>
    </collision>
  </link>
  <joint name="right_thumb_4_joint" type="revolute">
    <origin xyz="0.0149571022375899 0.0170124132550165 -0.00120000000000001" rpy="0 0 0" />
    <parent link="right_thumb_3" />
    <child link="right_thumb_4" />
    <axis xyz="0 0 1" />
    <limit lower="0" upper="0.2775" effort="50" velocity="1" />
    <mimic joint="right_thumb_3_joint" multiplier="0.7508" offset="0" />
  </joint>
  <link name="right_index_1">
    <inertial>
      <origin xyz="0.000852715296526529 0.0119735955318245 -0.00599986563267159" rpy="0 0 0" />
      <mass value="0.01229" />
      <inertia ixx="1.93998e-06" ixy="-1.5035e-07" ixz="-4.1e-10" iyy="5.6245e-07" iyz="-3.49e-09" izz="2.05872e-06" />
    </inertial>
    <visual>
      <origin xyz="0 0 0" rpy="0 0 0" />
      <geometry>
        <mesh filename="package://T170A/meshes/hands/right_index_1.STL" />
      </geometry>
      <material name="">
        <color rgba="1 1 1 1" />
      </material>
    </visual>
    <collision>
      <origin xyz="0 0 0" rpy="0 0 0" />
      <geometry>
        <mesh filename="package://T170A/meshes/hands/right_index_1.STL" />
      </geometry>
    </collision>
  </link>
  <joint name="right_index_1_joint" type="revolute">
    <origin xyz="-0.000285333323388565 0.0202750317161709 0.136945958498439" rpy="1.53588974175501 0 0" />
    <parent link="right_hand_base_link" />
    <child link="right_index_1" />
    <axis xyz="0 -0.0697564737441209 -0.997564050259825" />
    <limit lower="0" upper="1.333" effort="50" velocity="1" />
  </joint>
  <link name="right_index_2">
    <inertial>
      <origin xyz="0.00408342999190195 0.0192600939391442 -0.00500000380847467" rpy="0 0 0" />
      <mass value="0.00633" />
      <inertia ixx="9.4327e-07" ixy="-3.8912e-07" ixz="-2.0000000000000002e-11" iyy="2.897e-07" iyz="-5e-11" izz="1.14024e-06" />
    </inertial>
    <visual>
      <origin xyz="0 0 0" rpy="0 0 0" />
      <geometry>
        <mesh filename="package://T170A/meshes/hands/right_index_2.STL" />
      </geometry>
      <material name="">
        <color rgba="1 1 1 1" />
      </material>
    </visual>
    <collision>
      <origin xyz="0 0 0" rpy="0 0 0" />
      <geometry>
        <mesh filename="package://T170A/meshes/hands/right_index_2.STL" />
      </geometry>
    </collision>
  </link>
  <joint name="right_index_2_joint" type="revolute">
    <origin xyz="0.0080992697963248 0.0310949249595195 -0.001" rpy="0 0 0" />
    <parent link="right_index_1" />
    <child link="right_index_2" />
    <axis xyz="0 0 -1" />
    <limit lower="0" upper="1.527" effort="50" velocity="1" />
    <mimic joint="right_index_1_joint" multiplier="1.1169" offset="0" />
  </joint>
  <link name="right_middle_1">
    <inertial>
      <origin xyz="0.000852855866232599 0.011973606798452 -0.00399984588006246" rpy="0 0 0" />
      <mass value="0.01229" />
      <inertia ixx="1.94e-06" ixy="-1.5036e-07" ixz="-9.899999999999999e-10" iyy="5.6248e-07" iyz="-5.01e-09" izz="2.05872e-06" />
    </inertial>
    <visual>
      <origin xyz="0 0 0" rpy="0 0 0" />
      <geometry>
        <mesh filename="package://T170A/meshes/hands/right_middle_1.STL" />
      </geometry>
      <material name="">
        <color rgba="1 1 1 1" />
      </material>
    </visual>
    <collision>
      <origin xyz="0 0 0" rpy="0 0 0" />
      <geometry>
        <mesh filename="package://T170A/meshes/hands/right_middle_1.STL" />
      </geometry>
    </collision>
  </link>
  <joint name="right_middle_1_joint" type="revolute">
    <origin xyz="-0.000285333314556269 0.00295000000023597 0.137100000000016" rpy="1.5707963267792 0 0" />
    <parent link="right_hand_base_link" />
    <child link="right_middle_1" />
    <axis xyz="0 0 -1" />
    <limit lower="0" upper="1.333" effort="50" velocity="1" />
  </joint>
  <link name="right_middle_2">
    <inertial>
      <origin xyz="0.0047113458880482 0.0203465768773643 -0.00500003269708214" rpy="0 0 0" />
      <mass value="0.00681" />
      <inertia ixx="1.18348e-06" ixy="-5.0397e-07" ixz="-0.0" iyy="3.558e-07" iyz="-0.0" izz="1.43878e-06" />
    </inertial>
    <visual>
      <origin xyz="0 0 0" rpy="0 0 0" />
      <geometry>
        <mesh filename="package://T170A/meshes/hands/right_middle_2.STL" />
      </geometry>
      <material name="">
        <color rgba="1 1 1 1" />
      </material>
    </visual>
    <collision>
      <origin xyz="0 0 0" rpy="0 0 0" />
      <geometry>
        <mesh filename="package://T170A/meshes/hands/right_middle_2.STL" />
      </geometry>
    </collision>
  </link>
  <joint name="right_middle_2_joint" type="revolute">
    <origin xyz="0.00809959893697584 0.0310948392266618 0.00100000000000044" rpy="0 0 0" />
    <parent link="right_middle_1" />
    <child link="right_middle_2" />
    <axis xyz="0 0 -1" />
    <limit lower="0" upper="1.527" effort="50" velocity="1" />
    <mimic joint="right_middle_1_joint" multiplier="1.1169" offset="0" />
  </joint>
  <link name="right_ring_1">
    <inertial>
      <origin xyz="0.00085245845917839 0.0119734648811593 -0.00599989251266642" rpy="0 0 0" />
      <mass value="0.01229" />
      <inertia ixx="1.93998e-06" ixy="-1.5033000000000002e-07" ixz="-5.1e-10" iyy="5.6244e-07" iyz="-3.52e-09" izz="2.05872e-06" />
    </inertial>
    <visual>
      <origin xyz="0 0 0" rpy="0 0 0" />
      <geometry>
        <mesh filename="package://T170A/meshes/hands/right_ring_1.STL" />
      </geometry>
      <material name="">
        <color rgba="1 1 1 1" />
      </material>
    </visual>
    <collision>
      <origin xyz="0 0 0" rpy="0 0 0" />
      <geometry>
        <mesh filename="package://T170A/meshes/hands/right_ring_1.STL" />
      </geometry>
    </collision>
  </link>
  <joint name="right_ring_1_joint" type="revolute">
    <origin xyz="-0.000285333323395365 -0.0182707111726564 0.136282456905841" rpy="1.62315620435472 0 0" />
    <parent link="right_hand_base_link" />
    <child link="right_ring_1" />
    <axis xyz="0 0 -1" />
    <limit lower="0" upper="1.333" effort="50" velocity="1" />
  </joint>
  <link name="right_ring_2">
    <inertial>
      <origin xyz="0.00408287363348225 0.0192599767415159 -0.00499998343104271" rpy="0 0 0" />
      <mass value="0.00633" />
      <inertia ixx="9.4329e-07" ixy="-3.8762e-07" ixz="-3.394e-08" iyy="2.9614999999999996e-07" iyz="-7.389e-08" izz="1.13377e-06" />
    </inertial>
    <visual>
      <origin xyz="0 0 0" rpy="0 0 0" />
      <geometry>
        <mesh filename="package://T170A/meshes/hands/right_ring_2.STL" />
      </geometry>
      <material name="">
        <color rgba="1 1 1 1" />
      </material>
    </visual>
    <collision>
      <origin xyz="0 0 0" rpy="0 0 0" />
      <geometry>
        <mesh filename="package://T170A/meshes/hands/right_ring_2.STL" />
      </geometry>
    </collision>
  </link>
  <joint name="right_ring_2_joint" type="revolute">
    <origin xyz="0.00809885846186154 0.0310950320965672 -0.001" rpy="0 0 0" />
    <parent link="right_ring_1" />
    <child link="right_ring_2" />
    <axis xyz="0 0 -1" />
    <limit lower="0" upper="1.527" effort="50" velocity="1" />
    <mimic joint="right_ring_1_joint" multiplier="1.1169" offset="0" />
  </joint>
  <link name="right_little_1">
    <inertial>
      <origin xyz="0.000851610973032574 0.0119735303202265 -0.00599989467442243" rpy="0 0 0" />
      <mass value="0.012289999999999999" />
      <inertia ixx="1.94e-06" ixy="-1.5023e-07" ixz="-3e-10" iyy="5.624199999999999e-07" iyz="-3.18e-09" izz="2.05872e-06" />
    </inertial>
    <visual>
      <origin xyz="0 0 0" rpy="0 0 0" />
      <geometry>
        <mesh filename="package://T170A/meshes/hands/right_little_1.STL" />
      </geometry>
      <material name="">
        <color rgba="1 1 1 1" />
      </material>
    </visual>
    <collision>
      <origin xyz="0 0 0" rpy="0 0 0" />
      <geometry>
        <mesh filename="package://T170A/meshes/hands/right_little_1.STL" />
      </geometry>
    </collision>
  </link>
  <joint name="right_little_1_joint" type="revolute">
    <origin xyz="-0.000285333323391146 -0.0374222941312603 0.134460099927073" rpy="1.67551608191454 0 0" />
    <parent link="right_hand_base_link" />
    <child link="right_little_1" />
    <axis xyz="0 0 -1" />
    <limit lower="0" upper="1.333" effort="50" velocity="1" />
  </joint>
  <link name="right_little_2">
    <inertial>
      <origin xyz="0.00273929963119374 0.0161600317264199 -0.00499667765900381" rpy="0 0 0" />
      <mass value="0.00525" />
      <inertia ixx="5.5787e-07" ixy="-2.175e-07" ixz="-0.0" iyy="1.8624e-07" iyz="-0.0" izz="6.690599999999999e-07" />
    </inertial>
    <visual>
      <origin xyz="0 0 0" rpy="0 0 0" />
      <geometry>
        <mesh filename="package://T170A/meshes/hands/right_little_2.STL" />
      </geometry>
      <material name="">
        <color rgba="1 1 1 1" />
      </material>
    </visual>
    <collision>
      <origin xyz="0 0 0" rpy="0 0 0" />
      <geometry>
        <mesh filename="package://T170A/meshes/hands/right_little_2.STL" />
      </geometry>
    </collision>
  </link>
  <joint name="right_little_2_joint" type="revolute">
    <origin xyz="0.0080966 0.031096 -0.001" rpy="0 0 0" />
    <parent link="right_little_1" />
    <child link="right_little_2" />
    <axis xyz="0 0 -1" />
    <limit lower="0" upper="1.527" effort="50" velocity="1" />
    <mimic joint="right_little_1_joint" multiplier="1.1169" offset="0" />
  </joint>
  <link name="left_shoulder_pitch_link">
    <inertial>
      <origin xyz="-0.00551209 -0.00015499 0.05753102" rpy="0 0 0" />
      <mass value="0.94519295" />
      <inertia ixx="0.00081405" ixy="-0.00000454" ixz="0.00003716" iyy="0.00088822" iyz="-0.00000146" izz="0.00067978" />
    </inertial>
    <visual>
      <origin xyz="0 0 0" rpy="0 0 0" />
      <geometry>
        <mesh filename="package://T170A/meshes/left_shoulder_pitch_link.STL" />
      </geometry>
      <material name="">
        <color rgba="0.792156862745098 0.819607843137255 0.933333333333333 1" />
      </material>
    </visual>
    <collision>
      <origin xyz="0 0 0" rpy="0 0 0" />
      <geometry>
        <mesh filename="package://T170A/meshes/left_shoulder_pitch_link.STL" />
      </geometry>
    </collision>
  </link>
  <joint name="left_shoulder_pitch" type="revolute">
    <origin xyz="0 0.262002696671741 0.0805000000000003" rpy="0 0 -3.14159265358979" />
    <parent link="waist_pitch_link" />
    <child link="left_shoulder_pitch_link" />
    <axis xyz="0 0 1" />
    <limit lower="-2.09" upper="0.087" effort="66" velocity="3.56" />
  </joint>
  <link name="left_shoulder_roll_link">
    <inertial>
      <origin xyz="0.08690955 0.01532447 -0.03078205" rpy="0 0 0" />
      <mass value="0.66444631" />
      <inertia ixx="0.00050189" ixy="-0.00015519" ixz="0.00005003" iyy="0.00135463" iyz="0.00000882" izz="0.00124434" />
    </inertial>
    <visual>
      <origin xyz="0 0 0" rpy="0 0 0" />
      <geometry>
        <mesh filename="package://T170A/meshes/left_shoulder_roll_link.STL" />
      </geometry>
      <material name="">
        <color rgba="0.898039215686275 0.917647058823529 0.929411764705882 1" />
      </material>
    </visual>
    <collision>
      <origin xyz="0 0 0" rpy="0 0 0" />
      <geometry>
        <mesh filename="package://T170A/meshes/left_shoulder_roll_link.STL" />
      </geometry>
    </collision>
  </link>
  <joint name="left_shoulder_roll" type="revolute">
    <origin xyz="0.0314999999999998 0 0.0629999999999987" rpy="1.5707963267949 0 1.5707963267949" />
    <parent link="left_shoulder_pitch_link" />
    <child link="left_shoulder_roll_link" />
    <axis xyz="0 0 1" />
    <limit lower="-0.52" upper="2.96" effort="66" velocity="3.56" />
  </joint>
  <link name="left_elbow_yaw_link">
    <inertial>
      <origin xyz="-0.00082712 -0.00002126 0.09208463" rpy="0 0 0" />
      <mass value="0.57830504" />
      <inertia ixx="0.00083929" ixy="-0.00000030" ixz="0.00001291" iyy="0.00085728" iyz="0.00000020" izz="0.00027223" />
    </inertial>
    <visual>
      <origin xyz="0 0 0" rpy="0 0 0" />
      <geometry>
        <mesh filename="package://T170A/meshes/left_elbow_yaw_link.STL" />
      </geometry>
      <material name="">
        <color rgba="0.898039215686275 0.917647058823529 0.929411764705882 1" />
      </material>
    </visual>
    <collision>
      <origin xyz="0 0 0" rpy="0 0 0" />
      <geometry>
        <mesh filename="package://T170A/meshes/left_elbow_yaw_link.STL" />
      </geometry>
    </collision>
  </link>
  <joint name="left_elbow_yaw" type="revolute">
    <origin xyz="0.140335104804239 0.0247448653175347 -0.0314999999999977" rpy="1.57079632679489 0 1.74532925199432" />
    <parent link="left_shoulder_roll_link" />
    <child link="left_elbow_yaw_link" />
    <axis xyz="0 0 1" />
    <limit lower="-1.57" upper="1.57" effort="34" velocity="3.87" />
  </joint>
  <link name="left_elbow_pitch_link">
    <inertial>
      <origin xyz="0.00000000 -0.06175984 -0.02982156" rpy="0 0 0" />
      <mass value="0.44339888" />
      <inertia ixx="0.00049068" ixy="0.00000000" ixz="0.00000000" iyy="0.00024339" iyz="0.00000065" izz="0.00042265" />
    </inertial>
    <visual>
      <origin xyz="0 0 0" rpy="0 0 0" />
      <geometry>
        <mesh filename="package://T170A/meshes/left_elbow_pitch_link.STL" />
      </geometry>
      <material name="">
        <color rgba="0.898039215686275 0.917647058823529 0.929411764705882 1" />
      </material>
    </visual>
    <collision>
      <origin xyz="0 0 0" rpy="0 0 0" />
      <geometry>
        <mesh filename="package://T170A/meshes/left_elbow_pitch_link.STL" />
      </geometry>
    </collision>
  </link>
  <joint name="left_elbow_pitch" type="revolute">
    <origin xyz="0.029600000000003 0 0.107500206872319" rpy="-1.5707963267949 0 -1.5707963267949" />
    <parent link="left_elbow_yaw_link" />
    <child link="left_elbow_pitch_link" />
    <axis xyz="0 0 1" />
    <limit lower="-1.92" upper="0" effort="34" velocity="3.87" />
  </joint>
  <link name="left_wrist_yaw_link">
    <inertial>
      <origin xyz="0.00000000 0.02155652 0.05963926" rpy="0 0 0" />
      <mass value="0.47407100" />
      <inertia ixx="0.00116949" ixy="0.00000000" ixz="-0.00000082" iyy="0.00108132" iyz="-0.00021043" izz="0.00022588" />
    </inertial>
    <visual>
      <origin xyz="0 0 0" rpy="0 0 0" />
      <geometry>
        <mesh filename="package://T170A/meshes/left_wrist_yaw_link.STL" />
      </geometry>
      <material name="">
        <color rgba="0.898039215686275 0.917647058823529 0.929411764705882 1" />
      </material>
    </visual>
    <collision>
      <origin xyz="0 0 0" rpy="0 0 0" />
      <geometry>
        <mesh filename="package://T170A/meshes/left_wrist_yaw_link.STL" />
      </geometry>
    </collision>
  </link>
  <joint name="left_wrist_yaw" type="revolute">
    <origin xyz="0 -0.103499793127681 -0.0296000000000011" rpy="1.5707963267949 0 0" />
    <parent link="left_elbow_pitch_link" />
    <child link="left_wrist_yaw_link" />
    <axis xyz="0 0 1" />
    <limit lower="-3.14" upper="3.14" effort="11" velocity="4.18" />
  </joint>
  <link name="left_wrist_pitch_link">
    <inertial>
      <origin xyz="-0.00025012 0.00003583 0.02741533" rpy="0 0 0" />
      <mass value="0.28016455" />
      <inertia ixx="0.00008690" ixy="0.00000026" ixz="0.00000707" iyy="0.00013184" iyz="-0.00000007" izz="0.00009907" />
    </inertial>
    <visual>
      <origin xyz="0 0 0" rpy="0 0 0" />
      <geometry>
        <mesh filename="package://T170A/meshes/left_wrist_pitch_link.STL" />
      </geometry>
      <material name="">
        <color rgba="0.529411764705882 0.549019607843137 0.549019607843137 1" />
      </material>
    </visual>
    <collision>
      <origin xyz="0 0 0" rpy="0 0 0" />
      <geometry>
        <mesh filename="package://T170A/meshes/left_wrist_pitch_link.STL" />
      </geometry>
    </collision>
  </link>
  <joint name="left_wrist_pitch" type="revolute">
    <origin xyz="0 0.0335000000000009 0.1455" rpy="-1.5707963267949 0 3.14159265358979" />
    <parent link="left_wrist_yaw_link" />
    <child link="left_wrist_pitch_link" />
    <axis xyz="0 0 -1" />
    <limit lower="-0.52" upper="0.52" effort="4.8" velocity="4.71" />
  </joint>
  <link name="left_wrist_roll_link">
    <inertial>
      <origin xyz="0.02437500 0.00000000 -0.02638057" rpy="0 0 0" />
      <mass value="0.04088512" />
      <inertia ixx="0.00003122" ixy="0.00000000" ixz="-0.00000263" iyy="0.00003859" iyz="0.00000000" izz="0.00001494" />
    </inertial>
    <visual>
      <origin xyz="0 0 0" rpy="0 0 0" />
      <geometry>
        <mesh filename="package://T170A/meshes/left_wrist_roll_link.STL" />
      </geometry>
      <material name="">
        <color rgba="0.898039215686275 0.917647058823529 0.929411764705882 1" />
      </material>
    </visual>
    <collision>
      <origin xyz="0 0 0" rpy="0 0 0" />
      <geometry>
        <mesh filename="package://T170A/meshes/left_wrist_roll_link.STL" />
      </geometry>
    </collision>
  </link>
  <joint name="left_wrist_roll" type="revolute">
    <origin xyz="0.0260000000000001 0 0.0335000000000021" rpy="-1.5707963267949 0 -1.57079632679489" />
    <parent link="left_wrist_pitch_link" />
    <child link="left_wrist_roll_link" />
    <axis xyz="0 0 1" />
    <limit lower="-1.57" upper="0.52" effort="4.8" velocity="4.71" />
  </joint>
  <!-- Left hand -->
  <link name="left_hand_base_link">
    <inertial>
      <origin xyz="0.00125804982596889 0.00181115978340497 0.069441813384378" rpy="0 0 0" />
      <mass value="0.38756" />
      <inertia ixx="0.00059831308" ixy="-5.60829e-06" ixz="-2.8701399999999997e-06" iyy="0.00050077156" iyz="-3.4830999999999997e-06" izz="0.00018467082" />
    </inertial>
    <visual>
      <origin xyz="0 0 0" rpy="0 0 0" />
      <geometry>
        <mesh filename="package://T170A/meshes/hands/left_hand_base_link.STL" />
      </geometry>
      <material name="">
        <color rgba="1 1 1 1" />
      </material>
    </visual>
    <collision>
      <origin xyz="0 0 0" rpy="0 0 0" />
      <geometry>
        <mesh filename="package://T170A/meshes/hands/left_hand_base_link.STL" />
      </geometry>
    </collision>
  </link>
  <joint name="left_hand_base" type="fixed">
    <origin xyz="0.037 0 -0.026" rpy="-1.5708 0 -1.5708" />
    <parent link="left_wrist_roll_link" />
    <child link="left_hand_base_link" />
    <axis xyz="0 0 0" />
  </joint>
  <link name="left_thumb_1">
    <inertial>
      <origin xyz="0.000853471678482959 -0.00482215750222577 -0.0048200002860689" rpy="0 0 0" />
      <mass value="0.00483" />
      <inertia ixx="1.9502e-07" ixy="3.536e-08" ixz="3.1e-09" iyy="1.4336e-07" iyz="7.9e-09" izz="1.6891e-07" />
    </inertial>
    <visual>
      <origin xyz="0 0 0" rpy="0 0 0" />
      <geometry>
        <mesh filename="package://T170A/meshes/hands/left_thumb_1.STL" />
      </geometry>
      <material name="">
        <color rgba="1 1 1 1" />
      </material>
    </visual>
    <collision>
      <origin xyz="0 0 0" rpy="0 0 0" />
      <geometry>
        <mesh filename="package://T170A/meshes/hands/left_thumb_1.STL" />
      </geometry>
    </collision>
  </link>
  <joint name="left_thumb_1_joint" type="revolute">
    <origin xyz="0.01696 -0.02045 0.06635" rpy="0 0 0" />
    <parent link="left_hand_base_link" />
    <child link="left_thumb_1" />
    <axis xyz="0 0 1" />
    <limit lower="0" upper="1.246165" effort="50" velocity="1" />
  </joint>
  <link name="left_thumb_2">
    <inertial>
      <origin xyz="-0.0194665821577184 0.0163039156062457 -0.00803846870341951" rpy="0 0 0" />
      <mass value="0.05759" />
      <inertia ixx="1.0666209999999999e-05" ixy="4.413609999999999e-06" ixz="5.150000000000001e-09" iyy="8.92353e-06" iyz="-2.59e-09" izz="1.700133e-05" />
    </inertial>
    <visual>
      <origin xyz="0 0 0" rpy="0 0 0" />
      <geometry>
        <mesh filename="package://T170A/meshes/hands/left_thumb_2.STL" />
      </geometry>
      <material name="">
        <color rgba="1 1 1 1" />
      </material>
    </visual>
    <collision>
      <origin xyz="0 0 0" rpy="0 0 0" />
      <geometry>
        <mesh filename="package://T170A/meshes/hands/left_thumb_2.STL" />
      </geometry>
    </collision>
  </link>
  <joint name="left_thumb_2_joint" type="revolute">
    <origin xyz="0.010735 -0.0090002 -0.0065" rpy="1.5708 0 1.8361" />
    <parent link="left_thumb_1" />
    <child link="left_thumb_2" />
    <axis xyz="0 0 -1" />
    <limit lower="0" upper="0.48" effort="50" velocity="1" />
  </joint>
  <link name="left_thumb_3">
    <inertial>
      <origin xyz="-0.009466620350846 0.00207562096651074 -0.00719989129239992" rpy="0 0 0" />
      <mass value="0.00985" />
      <inertia ixx="1.21069e-06" ixy="1.0767e-07" ixz="1.0000000000000001e-11" iyy="6.011799999999999e-07" iyz="3e-11" izz="1.28966e-06" />
    </inertial>
    <visual>
      <origin xyz="0 0 0" rpy="0 0 0" />
      <geometry>
        <mesh filename="package://T170A/meshes/hands/left_thumb_3.STL" />
      </geometry>
      <material name="">
        <color rgba="1 1 1 1" />
      </material>
    </visual>
    <collision>
      <origin xyz="0 0 0" rpy="0 0 0" />
      <geometry>
        <mesh filename="package://T170A/meshes/hands/left_thumb_3.STL" />
      </geometry>
    </collision>
  </link>
  <joint name="left_thumb_3_joint" type="revolute">
    <origin xyz="-0.037617 0.041486 -0.0008" rpy="0 0 0" />
    <parent link="left_thumb_2" />
    <child link="left_thumb_3" />
    <axis xyz="0 0 -1" />
    <limit lower="0" upper="0.3578" effort="50" velocity="1" />
    <mimic joint="left_thumb_2_joint" multiplier="1.1425" offset="0" />
  </joint>
  <link name="left_thumb_4">
    <inertial>
      <origin xyz="-0.00604903882220686 0.00861521192699925 -0.00600331217685268" rpy="0 0 0" />
      <mass value="0.00552" />
      <inertia ixx="3.1668e-07" ixy="4.536e-08" ixz="-1.0000000000000001e-11" iyy="1.2999000000000001e-07" iyz="-4e-10" izz="3.3747e-07" />
    </inertial>
    <visual>
      <origin xyz="0 0 0" rpy="0 0 0" />
      <geometry>
        <mesh filename="package://T170A/meshes/hands/left_thumb_4.STL" />
      </geometry>
      <material name="">
        <color rgba="1 1 1 1" />
      </material>
    </visual>
    <collision>
      <origin xyz="0 0 0" rpy="0 0 0" />
      <geometry>
        <mesh filename="package://T170A/meshes/hands/left_thumb_4.STL" />
      </geometry>
    </collision>
  </link>
  <joint name="left_thumb_4_joint" type="revolute">
    <origin xyz="-0.014957 0.017012 -0.0012" rpy="0 0 0" />
    <parent link="left_thumb_3" />
    <child link="left_thumb_4" />
    <axis xyz="0 0 -1" />
    <limit lower="0" upper="0.2775" effort="50" velocity="1" />
    <mimic joint="left_thumb_3_joint" multiplier="0.7508" offset="0" />
  </joint>
  <link name="left_index_1">
    <inertial>
      <origin xyz="0.0008527159848849 0.0119736084448001 0.00599989169039383" rpy="0 0 0" />
      <mass value="0.012289999999999999" />
      <inertia ixx="1.93998e-06" ixy="1.5035e-07" ixz="4.1e-10" iyy="5.6245e-07" iyz="3.49e-09" izz="2.05872e-06" />
    </inertial>
    <visual>
      <origin xyz="0 0 0" rpy="0 0 0" />
      <geometry>
        <mesh filename="package://T170A/meshes/hands/left_index_1.STL" />
      </geometry>
      <material name="">
        <color rgba="1 1 1 1" />
      </material>
    </visual>
    <collision>
      <origin xyz="0 0 0" rpy="0 0 0" />
      <geometry>
        <mesh filename="package://T170A/meshes/hands/left_index_1.STL" />
      </geometry>
    </collision>
  </link>
  <joint name="left_index_1_joint" type="revolute">
    <origin xyz="-0.00028533 -0.020275 0.13695" rpy="1.6057 0 0" />
    <parent link="left_hand_base_link" />
    <child link="left_index_1" />
    <axis xyz="0 0 -1" />
    <limit lower="0" upper="1.333" effort="50" velocity="1" />
  </joint>
  <link name="left_index_2">
    <inertial>
      <origin xyz="0.00408344708691732 0.0192601764486991 0.00500003100756935" rpy="0 0 0" />
      <mass value="0.00633" />
      <inertia ixx="9.4327e-07" ixy="3.8912e-07" ixz="2.0000000000000002e-11" iyy="2.897e-07" iyz="5e-11" izz="1.14024e-06" />
    </inertial>
    <visual>
      <origin xyz="0 0 0" rpy="0 0 0" />
      <geometry>
        <mesh filename="package://T170A/meshes/hands/left_index_2.STL" />
      </geometry>
      <material name="">
        <color rgba="1 1 1 1" />
      </material>
    </visual>
    <collision>
      <origin xyz="0 0 0" rpy="0 0 0" />
      <geometry>
        <mesh filename="package://T170A/meshes/hands/left_index_2.STL" />
      </geometry>
    </collision>
  </link>
  <joint name="left_index_2_joint" type="revolute">
    <origin xyz="0.0080993 0.031095 0.001" rpy="0 0 0" />
    <parent link="left_index_1" />
    <child link="left_index_2" />
    <axis xyz="0 0 -1" />
    <limit lower="0" upper="1.527" effort="50" velocity="1" />
    <mimic joint="left_index_1_joint" multiplier="1.1169" offset="0" />
  </joint>
  <link name="left_middle_1">
    <inertial>
      <origin xyz="0.00085287755691596 0.0119736405947354 0.00599988891959347" rpy="0 0 0" />
      <mass value="0.012289999999999999" />
      <inertia ixx="1.94e-06" ixy="1.5036e-07" ixz="9.899999999999999e-10" iyy="5.6248e-07" iyz="5.01e-09" izz="2.05872e-06" />
    </inertial>
    <visual>
      <origin xyz="0 0 0" rpy="0 0 0" />
      <geometry>
        <mesh filename="package://T170A/meshes/hands/left_middle_1.STL" />
      </geometry>
      <material name="">
        <color rgba="1 1 1 1" />
      </material>
    </visual>
    <collision>
      <origin xyz="0 0 0" rpy="0 0 0" />
      <geometry>
        <mesh filename="package://T170A/meshes/hands/left_middle_1.STL" />
      </geometry>
    </collision>
  </link>
  <joint name="left_middle_1_joint" type="revolute">
    <origin xyz="-0.00028533 -0.00095 0.1371" rpy="1.5708 0 0" />
    <parent link="left_hand_base_link" />
    <child link="left_middle_1" />
    <axis xyz="0 0 -1" />
    <limit lower="0" upper="1.333" effort="50" velocity="1" />
  </joint>
  <link name="left_middle_2">
    <inertial>
      <origin xyz="0.00471131608223271 0.0203464425452461 0.00500013550498847" rpy="0 0 0" />
      <mass value="0.006809999999999999" />
      <inertia ixx="1.18348e-06" ixy="5.0397e-07" ixz="0.0" iyy="3.558e-07" iyz="0.0" izz="1.43878e-06" />
    </inertial>
    <visual>
      <origin xyz="0 0 0" rpy="0 0 0" />
      <geometry>
        <mesh filename="package://T170A/meshes/hands/left_middle_2.STL" />
      </geometry>
      <material name="">
        <color rgba="1 1 1 1" />
      </material>
    </visual>
    <collision>
      <origin xyz="0 0 0" rpy="0 0 0" />
      <geometry>
        <mesh filename="package://T170A/meshes/hands/left_middle_2.STL" />
      </geometry>
    </collision>
  </link>
  <joint name="left_middle_2_joint" type="revolute">
    <origin xyz="0.0080996 0.031095 0.001" rpy="0 0 0" />
    <parent link="left_middle_1" />
    <child link="left_middle_2" />
    <axis xyz="0 0 -1" />
    <limit lower="0" upper="1.527" effort="50" velocity="1" />
    <mimic joint="left_middle_1_joint" multiplier="1.1169" offset="0" />
  </joint>
  <link name="left_ring_1">
    <inertial>
      <origin xyz="0.000852611292407851 0.0119736634067538 0.00599988335942421" rpy="0 0 0" />
      <mass value="0.012289999999999999" />
      <inertia ixx="1.93998e-06" ixy="1.5033000000000002e-07" ixz="5.1e-10" iyy="5.6244e-07" iyz="3.52e-09" izz="2.05872e-06" />
    </inertial>
    <visual>
      <origin xyz="0 0 0" rpy="0 0 0" />
      <geometry>
        <mesh filename="package://T170A/meshes/hands/left_ring_1.STL" />
      </geometry>
      <material name="">
        <color rgba="1 1 1 1" />
      </material>
    </visual>
    <collision>
      <origin xyz="0 0 0" rpy="0 0 0" />
      <geometry>
        <mesh filename="package://T170A/meshes/hands/left_ring_1.STL" />
      </geometry>
    </collision>
  </link>
  <joint name="left_ring_1_joint" type="revolute">
    <origin xyz="-0.00028533 0.018271 0.13628" rpy="1.5184 0 0" />
    <parent link="left_hand_base_link" />
    <child link="left_ring_1" />
    <axis xyz="0 0 -1" />
    <limit lower="0" upper="1.333" effort="50" velocity="1" />
  </joint>
  <link name="left_ring_2">
    <inertial>
      <origin xyz="0.00408299506259779 0.0192602956948013 0.00500000332159135" rpy="0 0 0" />
      <mass value="0.00633" />
      <inertia ixx="9.4329e-07" ixy="3.8762e-07" ixz="3.394e-08" iyy="2.9614999999999996e-07" iyz="7.389e-08" izz="1.13377e-06" />
    </inertial>
    <visual>
      <origin xyz="0 0 0" rpy="0 0 0" />
      <geometry>
        <mesh filename="package://T170A/meshes/hands/left_ring_2.STL" />
      </geometry>
      <material name="">
        <color rgba="1 1 1 1" />
      </material>
    </visual>
    <collision>
      <origin xyz="0 0 0" rpy="0 0 0" />
      <geometry>
        <mesh filename="package://T170A/meshes/hands/left_ring_2.STL" />
      </geometry>
    </collision>
  </link>
  <joint name="left_ring_2_joint" type="revolute">
    <origin xyz="0.0080989 0.031095 0.001" rpy="0 0 0" />
    <parent link="left_ring_1" />
    <child link="left_ring_2" />
    <axis xyz="0 0 -1" />
    <limit lower="0" upper="1.527" effort="50" velocity="1" />
    <mimic joint="left_ring_1_joint" multiplier="1.1169" offset="0" />
  </joint>
  <link name="left_little_1">
    <inertial>
      <origin xyz="0.000851752984712406 0.0119737230065286 0.00599988919520877" rpy="0 0 0" />
      <mass value="0.012289999999999999" />
      <inertia ixx="1.94e-06" ixy="1.5023e-07" ixz="3e-10" iyy="5.624199999999999e-07" iyz="3.18e-09" izz="2.05872e-06" />
    </inertial>
    <visual>
      <origin xyz="0 0 0" rpy="0 0 0" />
      <geometry>
        <mesh filename="package://T170A/meshes/hands/left_little_1.STL" />
      </geometry>
      <material name="">
        <color rgba="1 1 1 1" />
      </material>
    </visual>
    <collision>
      <origin xyz="0 0 0" rpy="0 0 0" />
      <geometry>
        <mesh filename="package://T170A/meshes/hands/left_little_1.STL" />
      </geometry>
    </collision>
  </link>
  <joint name="left_little_1_joint" type="revolute">
    <origin xyz="-0.00028533 0.037422 0.13446" rpy="1.4661 0 0" />
    <parent link="left_hand_base_link" />
    <child link="left_little_1" />
    <axis xyz="0 0 -1" />
    <limit lower="0" upper="1.333" effort="50" velocity="1" />
  </joint>
  <link name="left_little_2">
    <inertial>
      <origin xyz="0.00273890807896854 0.0161632709360688 0.00500586036971424" rpy="0 0 0" />
      <mass value="0.00525" />
      <inertia ixx="5.5787e-07" ixy="2.175e-07" ixz="0.0" iyy="1.8624e-07" iyz="0.0" izz="6.690599999999999e-07" />
    </inertial>
    <visual>
      <origin xyz="0 0 0" rpy="0 0 0" />
      <geometry>
        <mesh filename="package://T170A/meshes/hands/left_little_2.STL" />
      </geometry>
      <material name="">
        <color rgba="1 1 1 1" />
      </material>
    </visual>
    <collision>
      <origin xyz="0 0 0" rpy="0 0 0" />
      <geometry>
        <mesh filename="package://T170A/meshes/hands/left_little_2.STL" />
      </geometry>
    </collision>
  </link>
  <joint name="left_little_2_joint" type="revolute">
    <origin xyz="0.0080966 0.031096 0.001" rpy="0 0 0" />
    <parent link="left_little_1" />
    <child link="left_little_2" />
    <axis xyz="0 0 -1" />
    <limit lower="0" upper="1.527" effort="50" velocity="1" />
    <mimic joint="left_little_1_joint" multiplier="1.1169" offset="0" />
  </joint>
  <link name="right_hip_yaw_link">
    <inertial>
      <origin xyz="0.00000000 -0.09429802 0.08120297" rpy="0 0 0" />
      <mass value="1.53718881" />
      <inertia ixx="0.00279936" ixy="0.00000000" ixz="0.00000000" iyy="0.00224082" iyz="0.00077765" izz="0.00204769" />
    </inertial>
    <visual>
      <origin xyz="0 0 0" rpy="0 0 0" />
      <geometry>
        <mesh filename="package://T170A/meshes/right_hip_yaw_link.STL" />
      </geometry>
      <material name="">
        <color rgba="0.898039215686275 0.917647058823529 0.929411764705882 1" />
      </material>
    </visual>
    <collision>
      <origin xyz="0 0 0" rpy="0 0 0" />
      <geometry>
        <mesh filename="package://T170A/meshes/right_hip_yaw_link.STL" />
      </geometry>
    </collision>
  </link>
  <joint name="right_hip_yaw" type="revolute">
    <origin xyz="0.0470000000000004 -0.105000000000001 -0.0276085525650127" rpy="3.14159265358979 0 1.5707963267949" />
    <parent link="base_link" />
    <child link="right_hip_yaw_link" />
    <axis xyz="0 0 1" />
    <limit lower="-0.52" upper="0.52" effort="63" velocity="6.38" />
  </joint>
  <link name="right_hip_roll_link">
    <inertial>
      <origin xyz="-0.01145017 0.00000000 0.06524942" rpy="0 0 0" />
      <mass value="2.87669901" />
      <inertia ixx="0.00557190" ixy="0.00000336" ixz="0.00026206" iyy="0.00639346" iyz="-0.00000004" izz="0.00602226" />
    </inertial>
    <visual>
      <origin xyz="0 0 0" rpy="0 0 0" />
      <geometry>
        <mesh filename="package://T170A/meshes/right_hip_roll_link.STL" />
      </geometry>
      <material name="">
        <color rgba="0.898039215686275 0.917647058823529 0.929411764705882 1" />
      </material>
    </visual>
    <collision>
      <origin xyz="0 0 0" rpy="0 0 0" />
      <geometry>
        <mesh filename="package://T170A/meshes/right_hip_roll_link.STL" />
      </geometry>
    </collision>
  </link>
  <joint name="right_hip_roll" type="revolute">
    <origin xyz="0 -0.0679999999999997 0.0899999999999999" rpy="-1.5707963267949 0 0" />
    <parent link="right_hip_yaw_link" />
    <child link="right_hip_roll_link" />
    <axis xyz="0 0 1" />
    <limit lower="-0.17" upper="0.17" effort="63" velocity="6.38" />
  </joint>
  <link name="right_hip_pitch_link">
    <inertial>
      <origin xyz="0.00323183 0.19509694 -0.06092567" rpy="0 0 0" />
      <mass value="4.81699722" />
      <inertia ixx="0.07539568" ixy="-0.00010600" ixz="-0.00031464" iyy="0.01039739" iyz="-0.00517958" izz="0.07373336" />
    </inertial>
    <visual>
      <origin xyz="0 0 0" rpy="0 0 0" />
      <geometry>
        <mesh filename="package://T170A/meshes/right_hip_pitch_link.STL" />
      </geometry>
      <material name="">
        <color rgba="0.898039215686275 0.917647058823529 0.929411764705882 1" />
      </material>
    </visual>
    <collision>
      <origin xyz="0 0 0" rpy="0 0 0" />
      <geometry>
        <mesh filename="package://T170A/meshes/right_hip_pitch_link.STL" />
      </geometry>
    </collision>
  </link>
  <joint name="right_hip_pitch" type="revolute">
    <origin xyz="0.0329999999999998 0 0.067997630557895" rpy="0 -1.5707963267949 3.1416" />
    <parent link="right_hip_roll_link" />
    <child link="right_hip_pitch_link" />
    <axis xyz="0 0 -1" />
    <limit lower="-0.17" upper="0.78" effort="267" velocity="5.75" />
  </joint>
  <link name="right_knee_pitch_link">
    <inertial>
      <origin xyz="-0.00127473 0.14104406 0.00795556" rpy="0 0 0" />
      <mass value="1.84028830" />
      <inertia ixx="0.02142491" ixy="0.00043342" ixz="-0.00013377" iyy="0.00166953" iyz="0.00197227" izz="0.02081935" />
    </inertial>
    <visual>
      <origin xyz="0 0 0" rpy="0 0 0" />
      <geometry>
        <mesh filename="package://T170A/meshes/right_knee_pitch_link.STL" />
      </geometry>
      <material name="">
        <color rgba="0.898039215686275 0.917647058823529 0.929411764705882 1" />
      </material>
    </visual>
    <collision>
      <origin xyz="0 0 0" rpy="0 0 0" />
      <geometry>
        <mesh filename="package://T170A/meshes/right_knee_pitch_link.STL" />
      </geometry>
    </collision>
  </link>
  <joint name="right_knee_pitch" type="revolute">
    <origin xyz="0 0.41999 -0.044" rpy="0 0 0" />
    <parent link="right_hip_pitch_link" />
    <child link="right_knee_pitch_link" />
    <axis xyz="0 0 1" />
    <limit lower="0" upper="1.57" effort="267" velocity="5.75" />
  </joint>
  <link name="right_ankle_pitch_link">
    <inertial>
      <origin xyz="0.00000000 0.00288428 -0.04013279" rpy="0 0 0" />
      <mass value="0.61370419" />
      <inertia ixx="0.00044839" ixy="0.00000000" ixz="0.00000000" iyy="0.00044212" iyz="-0.00000076" izz="0.00030173" />
    </inertial>
    <visual>
      <origin xyz="0 0 0" rpy="0 0 0" />
      <geometry>
        <mesh filename="package://T170A/meshes/right_ankle_pitch_link.STL" />
      </geometry>
      <material name="">
        <color rgba="0.529411764705882 0.549019607843137 0.549019607843137 1" />
      </material>
    </visual>
    <collision>
      <origin xyz="0 0 0" rpy="0 0 0" />
      <geometry>
        <mesh filename="package://T170A/meshes/right_ankle_pitch_link.STL" />
      </geometry>
    </collision>
  </link>
  <joint name="right_ankle_pitch" type="revolute">
    <origin xyz="0 0.37 -0.0284999999999996" rpy="3.14159265358979 0 -1.5707963267949" />
    <parent link="right_knee_pitch_link" />
    <child link="right_ankle_pitch_link" />
    <axis xyz="0 0 1" />
    <limit lower="-1.04" upper="1.04" effort="42" velocity="7.12" />
  </joint>
  <link name="right_ankle_roll_link">
    <inertial>
      <origin xyz="0.00131918 -0.06909036 0.00357324" rpy="0 0 0" />
      <mass value="0.88500968" />
      <inertia ixx="0.00343946" ixy="0.00001743" ixz="0.00003151" iyy="0.00312243" iyz="0.00021872" izz="0.00098214" />
    </inertial>
    <visual>
      <origin xyz="0 0 0" rpy="0 0 0" />
      <geometry>
        <mesh filename="package://T170A/meshes/right_ankle_roll_link.STL" />
      </geometry>
      <material name="">
        <color rgba="0.647058823529412 0.619607843137255 0.588235294117647 1" />
      </material>
    </visual>
    <collision>
      <origin xyz="0 0 0" rpy="0 0 0" />
      <geometry>
        <mesh filename="package://T170A/meshes/right_ankle_roll_link.STL" />
      </geometry>
    </collision>
  </link>
  <joint name="right_ankle_roll" type="revolute">
    <origin xyz="0 -0.0260999999999999 -0.0396999999999966" rpy="1.5707963267949 1.5707963267949 0" />
    <parent link="right_ankle_pitch_link" />
    <child link="right_ankle_roll_link" />
    <axis xyz="0 0 1" />
    <limit lower="-0.087" upper="0.087" effort="23" velocity="7.85" />
  </joint>
  <link name="left_hip_yaw_link">
    <inertial>
      <origin xyz="0.00000000 -0.09429802 0.08120297" rpy="0 0 0" />
      <mass value="1.53718881" />
      <inertia ixx="0.00279936" ixy="0.00000000" ixz="0.00000000" iyy="0.00224082" iyz="0.00077765" izz="0.00204769" />
    </inertial>
    <visual>
      <origin xyz="0 0 0" rpy="0 0 0" />
      <geometry>
        <mesh filename="package://T170A/meshes/left_hip_yaw_link.STL" />
      </geometry>
      <material name="">
        <color rgba="0.898039215686275 0.917647058823529 0.929411764705882 1" />
      </material>
    </visual>
    <collision>
      <origin xyz="0 0 0" rpy="0 0 0" />
      <geometry>
        <mesh filename="package://T170A/meshes/left_hip_yaw_link.STL" />
      </geometry>
    </collision>
  </link>
  <joint name="left_hip_yaw" type="revolute">
    <origin xyz="0.0470000000000006 0.105 -0.0276085525650127" rpy="-3.14159265358979 0 1.5707963267949" />
    <parent link="base_link" />
    <child link="left_hip_yaw_link" />
    <axis xyz="0 0 1" />
    <limit lower="-0.52" upper="0.52" effort="63" velocity="6.38" />
  </joint>
  <link name="left_hip_roll_link">
    <inertial>
      <origin xyz="0.01127636 0.00001818 0.06505569" rpy="0 0 0" />
      <mass value="2.87669901" />
      <inertia ixx="0.00557200" ixy="0.00000343" ixz="-0.00025836" iyy="0.00638667" iyz="-0.00000014" izz="0.00601542" />
    </inertial>
    <visual>
      <origin xyz="0 0 0" rpy="0 0 0" />
      <geometry>
        <mesh filename="package://T170A/meshes/left_hip_roll_link.STL" />
      </geometry>
      <material name="">
        <color rgba="0.792156862745098 0.819607843137255 0.929411764705882 1" />
      </material>
    </visual>
    <collision>
      <origin xyz="0 0 0" rpy="0 0 0" />
      <geometry>
        <mesh filename="package://T170A/meshes/left_hip_roll_link.STL" />
      </geometry>
    </collision>
  </link>
  <joint name="left_hip_roll" type="revolute">
    <origin xyz="0 -0.0679999999999999 0.0900000000000001" rpy="-1.5707963267949 0 0" />
    <parent link="left_hip_yaw_link" />
    <child link="left_hip_roll_link" />
    <axis xyz="0 0 1" />
    <limit lower="-0.17" upper="0.17" effort="63" velocity="6.38" />
  </joint>
  <link name="left_hip_pitch_link">
    <inertial>
      <origin xyz="0.00299948 -0.19512097 -0.06095991" rpy="0 0 0" />
      <mass value="4.81689757" />
      <inertia ixx="0.07537227" ixy="0.00011453" ixz="-0.00031608" iyy="0.01038450" iyz="0.00517132" izz="0.07372453" />
    </inertial>
    <visual>
      <origin xyz="0 0 0" rpy="0 0 0" />
      <geometry>
        <mesh filename="package://T170A/meshes/left_hip_pitch_link.STL" />
      </geometry>
      <material name="">
        <color rgba="0.898039215686275 0.917647058823529 0.929411764705882 1" />
      </material>
    </visual>
    <collision>
      <origin xyz="0 0 0" rpy="0 0 0" />
      <geometry>
        <mesh filename="package://T170A/meshes/left_hip_pitch_link.STL" />
      </geometry>
    </collision>
  </link>
  <joint name="left_hip_pitch" type="revolute">
    <origin xyz="-0.0331999999999998 0 0.0680000000000001" rpy="3.14159265358979 -1.5707963267949 3.1416" />
    <parent link="left_hip_roll_link" />
    <child link="left_hip_pitch_link" />
    <axis xyz="0 0 -1" />
    <limit lower="-0.78" upper="0.17" effort="267" velocity="5.75" />
  </joint>
  <link name="left_knee_pitch_link">
    <inertial>
      <origin xyz="-0.00302329 -0.14450002 0.00792567" rpy="0 0 0" />
      <mass value="1.84028681" />
      <inertia ixx="0.02267720" ixy="-0.00084929" ixz="-0.00025369" iyy="0.00177826" iyz="-0.00222368" izz="0.02217161" />
    </inertial>
    <visual>
      <origin xyz="0 0 0" rpy="0 0 0" />
      <geometry>
        <mesh filename="package://T170A/meshes/left_knee_pitch_link.STL" />
      </geometry>
      <material name="">
        <color rgba="0.898039215686275 0.917647058823529 0.929411764705882 1" />
      </material>
    </visual>
    <collision>
      <origin xyz="0 0 0" rpy="0 0 0" />
      <geometry>
        <mesh filename="package://T170A/meshes/left_knee_pitch_link.STL" />
      </geometry>
    </collision>
  </link>
  <joint name="left_knee_pitch" type="revolute">
    <origin xyz="-0.00020000000003453 -0.42 -0.044" rpy="0 0 0" />
    <parent link="left_hip_pitch_link" />
    <child link="left_knee_pitch_link" />
    <axis xyz="0 0 1" />
    <limit lower="-1.57" upper="0" effort="267" velocity="5.75" />
  </joint>
  <link name="left_ankle_pitch_link">
    <inertial>
      <origin xyz="0.00000000 -0.00288431 -0.04038698" rpy="0 0 0" />
      <mass value="0.61370463" />
      <inertia ixx="0.00044828" ixy="0.00000000" ixz="0.00000000" iyy="0.00044201" iyz="0.00000068" izz="0.00030173" />
    </inertial>
    <visual>
      <origin xyz="0 0 0" rpy="0 0 0" />
      <geometry>
        <mesh filename="package://T170A/meshes/left_ankle_pitch_link.STL" />
      </geometry>
      <material name="">
        <color rgba="0.529411764705882 0.549019607843137 0.549019607843137 1" />
      </material>
    </visual>
    <collision>
      <origin xyz="0 0 0" rpy="0 0 0" />
      <geometry>
        <mesh filename="package://T170A/meshes/left_ankle_pitch_link.STL" />
      </geometry>
    </collision>
  </link>
  <joint name="left_ankle_pitch" type="revolute">
    <origin xyz="0 -0.37 -0.0285000000000001" rpy="-3.14159265358979 0 1.5707963267949" />
    <parent link="left_knee_pitch_link" />
    <child link="left_ankle_pitch_link" />
    <axis xyz="0 0 1" />
    <limit lower="-1.04" upper="1.04" effort="42" velocity="7.12" />
  </joint>
  <link name="left_ankle_roll_link">
    <inertial>
      <origin xyz="-0.00130381 -0.06909381 0.00357445" rpy="0 0 0" />
      <mass value="0.88510769" />
      <inertia ixx="0.00344001" ixy="-0.00001755" ixz="-0.00003129" iyy="0.00312303" iyz="0.00021873" izz="0.00098228" />
    </inertial>
    <visual>
      <origin xyz="0 0 0" rpy="0 0 0" />
      <geometry>
        <mesh filename="package://T170A/meshes/left_ankle_roll_link.STL" />
      </geometry>
      <material name="">
        <color rgba="0.647058823529412 0.619607843137255 0.588235294117647 1" />
      </material>
    </visual>
    <collision>
      <origin xyz="0 0 0" rpy="0 0 0" />
      <geometry>
        <mesh filename="package://T170A/meshes/left_ankle_roll_link.STL" />
      </geometry>
    </collision>
  </link>
  <joint name="left_ankle_roll" type="revolute">
    <origin xyz="0 0.0261 -0.0400000000000032" rpy="-1.5707963267949 -1.5707963267949 0" />
    <parent link="left_ankle_pitch_link" />
    <child link="left_ankle_roll_link" />
    <axis xyz="0 0 1" />
    <limit lower="-0.087" upper="0.087" effort="23" velocity="7.85" />
  </joint>
</robot>
